Workbook

Sheet FOH & BOH
A1: =+SUMMARY!A7 -> PAYROLL 25TH JUNE - 21 JULY 22 UGLY DUMPLING TEAM
A5: Employee Reference | B5: Employee Forename | C5: Employee Surname | D5: Pay Comp. Description | E5: H. Rate | F5: Units | G5: Pay | H5: Perf. Bonus | I5: Bonus | J5: Status | K5: S.Charge | L5: Notes
A6: Waitress | B6: Tamar | C6: Molina Rios | D6: Hourly Rate | E6: 9.5 | F6: 216.09 | G6: =E6*F6 -> 2052.855 | H6: 150 | K6: 2.5
A7: Ass. Manager | B7: Lissette | C7: Paredes | D7: Hourly Rate | E7: 10.5 | F7: 0 | G7: =E7*F7 -> 0 | H7: 0
A8: Ass. Manager | B8: Melanny Salome | C8: Folleco Chala | D8: Hourly Rate | E8: 10 | F8: 137.92 | G8: =E8*F8 -> 1379.2 | H8: 100
A9: Manager | B9: Sergio | C9: Ferrerosa | D9: Hourly Rate | E9: 10.5 | F9: 191.19 | G9: =E9*F9 -> 2007.495 | H9: 120 | K9: 3.5
A10: Ass. Manager | B10: David Daniel | C10: Molina Rios | D10: Hourly Rate | E10: 10.5 | F10: 195.76 | G10: =E10*F10 -> 2055.48 | H10: 130 | K10: 3
A11: Waitress | B11: Rochelle | C11: Jayaraj | D11: Hourly Rate | E11: 9 | F11: 190.89 | G11: =E11*F11 -> 1718.01 | K11: 1
A12: Waitress | B12: Karina | C12: Kavdanska | D12: Hourly Rate | E12: 9 | F12: 119.62 | G12: =E12*F12 -> 1076.58 | K12: 1 | L12: pay rise £9
A13: Waitress | B13: Ciara | C13: Bates | D13: Hourly Rate | E13: 9 | F13: 65.61 | G13: =E13*F13 -> 590.49 | K13: 1 | L13: LEAVER
A14: Waitress | B14: Rebecca | C14: Archibold | D14: Hourly Rate | E14: 9 | F14: 107.91 | G14: =E14*F14 -> 971.19 | K14: 1
A15: Waitress | B15: Endea | C15: Stractchan | D15: Hourly Rate | E15: 9 | F15: 81.31 | G15: =E15*F15 -> 731.79 | K15: 0.5 | L15: Starter
A16: Waitress | B16: Shania | C16: Malcolm | D16: Hourly Rate | E16: 9.5 | F16: 110.34 | G16: =E16*F16 -> 1048.23 | K16: 0.5
A17: Waitress | B17: Benjamin | C17: Gray | D17: Hourly Rate | E17: 8.5 | F17: 72.61 | G17: =E17*F17 -> 617.185 | K17: 0.5 | L17: Starter
A18: Waitress | B18: Blean | C18: Anteneh | D18: Hourly Rate | E18: 8.5 | F18: 15 | G18: =E18*F18 -> 127.5 | L18: LEAVER
A19: Waitress | B19: Peace | C19: Imwensi | D19: Hourly Rate | E19: 8.5 | F19: 31.06 | G19: =E19*F19 -> 264.01 | K19: 0.5 | L19: Starter
A20: Waitress | B20: Gabrielle | C20: Prah | D20: Hourly Rate | E20: 8.5 | F20: 35.85 | G20: =E20*F20 -> 304.725 | K20: 1 | L20: starter/leaver
A21: Waitress | B21: Glenn | C21: Taniegra | D21: Hourly Rate | E21: 9.5 | F21: 129.86 | G21: =E21*F21 -> 1233.67 | K21: 1 | L21: Starter
A22: FOH&BOH | B22: Hubert | C22: Siotor | D22: Hourly Rate | E22: 10.5 | F22: 20.39 | G22: =E22*F22 -> 214.095 | K22: 1 | L22: Starter
A23: Waitress | B23: Jc Marinel | C23: Navea | D23: Hourly Rate | E23: 8 | F23: 42.03 | G23: =E23*F23 -> 336.24 | K23: 0.5
A25: Serior Chef | B25: Lorna | C25: Lau | D25: Hourly Rate | E25: 10 | F25: 29.64 | G25: =E25*F25 -> 296.4
A26: Kitchen Manager | B26: Dimitris | C26: Papachristos | D26: Hourly Rate | E26: 10.7 | F26: 100.18 | G26: =E26*F26 -> 1071.926 | H26: 100 | L26: Holiday
A27: Kitchen Manager | B27: Jean Carlos | C27: Garcia Gonzalez | D27: Hourly Rate | E27: 10.7 | F27: 25 | G27: =E27*F27 -> 267.5 | L27: Month sick pay
A28: Prod. Team | B28: Wai Pink (Jess) | C28: Cham | D28: Hourly Rate | E28: 10 | F28: ='Dumpling Bonus '!L8 -> 119.1 | G28: =E28*F28 -> 1191 | I28: ='Dumpling Bonus '!J8 -> 145.425
A29: Prod. Team | B29: Auntie WING | C29: Auntie Wing | D29: Hourly Rate | E29: 10 | F29: ='Dumpling Bonus '!L7 -> 135.82 | G29: =E29*F29 -> 1358.2 | I29: ='Dumpling Bonus '!J7 -> 134.575
A30: Prod. Team | B30: Kitty | C30: Oil Lan | D30: Hourly Rate | E30: 9.5 | F30: 147.94 | G30: =E30*F30 -> 1405.43 | I30: 50
A31: Kitchen Staff | B31: Bruno | C31: Martins | D31: Hourly Rate | E31: 9.5 | F31: 195.42 | G31: =E31*F31 -> 1856.49 | H31: 70 | K31: 1 | L31: Pay rise £9.5
A32: Junior chef | B32: Adalgisa | C32: Vargas Feliz | D32: Hourly Rate | E32: 9.5 | F32: =16*5 -> 80 | G32: =E32*F32 -> 760 | K32: 3
A33: Junior chef | B33: Naomi Jhuliana | C33: Vallejos | D33: Hourly Rate | E33: 9 | F33: 95.53 | G33: =E33*F33 -> 859.77 | K33: 0.5 | L33: pay rise £9
A34: Junior chef | B34: Leonor | C34: Ferreira | D34: Hourly Rate | E34: 8 | F34: 93.62 | G34: =E34*F34 -> 748.96 | K34: 0.5
A35: Junior chef | B35: Ria | C35: McIntosh Henry | D35: Hourly Rate | E35: 10 | F35: 14.45 | G35: =E35*F35 -> 144.5 | K35: 1 | L35: starter/leaver
A36: Junior chef | B36: Agata | C36: Drobinska | D36: Hourly Rate | E36: 8.5 | F36: 143.77 | G36: =E36*F36 -> 1222.045 | K36: 1
A37: Junior chef | B37: Saicharan | C37: Manapalli | D37: Hourly Rate | E37: 10 | F37: 237.32 | G37: =E37*F37 -> 2373.2 | H37: 130 | K37: 1
A38: Prod. Team | B38: Ling | C38: Chak | D38: Hourly Rate | E38: 9.5 | F38: 229.33 | G38: =E38*F38 -> 2178.635 | I38: 60
A39: Prod. Team | B39: Loh Kai Xuan Tabi | D39: Hourly Rate | E39: 8.5 | F39: 26.71 | G39: =E39*F39 -> 227.035 | I39: 50
A40: Junior chef | B40: Olga | C40: Chala Quilumba | D40: Hourly Rate | E40: 9.5 | F40: 108.04 | G40: =E40*F40 -> 1026.38 | K40: 2
A41: Junior chef | B41: Anny Belkys | C41: Matos | D41: Hourly Rate | E41: 9.5 | F41: 135.04 | G41: =E41*F41 -> 1282.88 | K41: 2
A42: Junior chef | B42: Hafiz Abdur | C42: Rahim | D42: Hourly Rate | E42: 9.5 | F42: 176.56 | G42: =E42*F42 -> 1677.32 | K42: 1 | L42: Starter
A43: Junior chef | B43: Mei Lin | C43: Khong | D43: Hourly Rate | E43: 9.5 | F43: 104.56 | G43: =E43*F43 -> 993.32 | I43: 50 | L43: Starter
A44: Kitchen Ass. manager | B44: Setareh | C44: Saeedfar | D44: Hourly Rate | E44: 10.7 | F44: 210.18 | G44: =E44*F44 -> 2248.926 | K44: 1 | L44: pay rise £10.7
...

Sheet SUMMARY
A7: PAYROLL 25TH JUNE - 21 JULY 22 UGLY DUMPLING TEAM
C13: TOTAL
B14: PAYROLL TOTAL | C14: ='FOH & BOH'!G51 -> 27547.995
B15: INCENTIVES | C15: ='FOH & BOH'!H51 -> 420
B16: DUMPLING BONUS | C16: ='FOH & BOH'!I51 -> 330
B17: HOLIDAYS TOTAL | C17: ='HOLIDAYS AND NOTES'!F10 -> 2609.6
B18: TOTAL PAYROLL | C18: =SUM(C14:C17) -> 30907.595

Sheet HOLIDAYS AND NOTES
C1: =+SUMMARY!A7 -> PAYROLL 25TH JUNE - 21 JULY 22 UGLY DUMPLING TEAM
A3: HOLIDAYS
A5: Employee Forename | B5: Employee Surname | C5: Pay Component Description | D5: Rate | E5: Units | F5: TOTAL | G5: STATUS
A6: Salome | D6: 10 | E6: =7*8 -> 56 | F6: =D6*E6 -> 560
A7: Dimitris | D7: 10.7 | E7: =12*8 -> 96 | F7: =D7*E7 -> 1027.2
A8: Ciara | D8: 9 | E8: =3.5*8 -> 28 | F8: =D8*E8 -> 252
D9: 10.7 | E9: =9*8 -> 72 | F9: =D9*E9 -> 770.4
A10: TOTAL | F10: =+SUM(F6:F9) -> 2609.6

Sheet STARTERS DETAILS 
B1: =+SUMMARY!A7 -> PAYROLL 25TH JUNE - 21 JULY 22 UGLY DUMPLING TEAM
A2: NOTES
B11: New Startes | C11: NINo | E11: Bank Account | F11: Sort Code | G11: Nationality | H11: Passaport nb | I11: Setlment status | J11: Share Code | K11: Resid. Card
B12: Hubert Filip Siotor
B13: Reyquane Tieye Kendell | C13: PK845982C | E13: 45683963 | F13: 77.04.40
B14: Peace Jasmine Imwensi | C14: PK718203D | E14: 18622987 | F14: 07.08.06
B15: Benjamin Gray | C15: HN291402C | E15: 22349502 | F15: 07.04.36
B16: Endea Stratchan | C16: PH099049C | E16: 37575256 | F16: 09.01.29
B17: Glenn Taniegra | C17: SN560166C | E17: 32192500 | F17: 40.04.00
B18: Gabrielle Prah | C18: SN100623D | E18: 04442962 | F18: 11.64.36
B19: Ria McIntosh Henry | C19: JM996211D | E19: 26546329 | F19: 07.04.36
B20: Adriana Llumiquinga Baca | C20: SS276685B | E20: 28183768 | F20: 77.91.30
B21: Lakshmi Vemula | C21: NJ749783D

Sheet Dumpling Bonus 
C6: Hours (deputy) | D6: Cash ded | E6: Dumlings (rep. wrappers) | F6: Total minus cash ded | G6: Hours red. By cash | I6: Total dump. Bonus | J6: Bonus | K6: bonus per hour | L6: hours after bonus
B7: Wing | C7: 205.82 | D7: =90*70 -> 6300 | E7: =15678+3500 -> 19178 | F7: =E7-D7 -> 12878 | G7: =C7-B14 -> 135.82 | H7: =G7*$B$12 -> 10186.5 | I7: =F7-H7 -> 2691.5 | J7: =I7*$B$11 -> 134.575 | K7: =J7/G7 -> 0.99083346 | L7: =C7-B14 -> 135.82
B8: Jess | C8: 189.1 | D8: =$B$13*B15 -> 6300 | E8: 18141 | F8: =E8-D8 -> 11841 | G8: =C8-B15 -> 119.1 | H8: =G8*$B$12 -> 8932.5 | I8: =F8-H8 -> 2908.5 | J8: =I8*$B$11 -> 145.425 | K8: =J8/G8 -> 1.2210327 | L8: =C8-B15 -> 119.1
A10: Ref
A11: Bonus per dumpling | B11: 0.05
A12: Target | B12: 75
A13: Cash per 90 dumpl | B13: 90
A14: wing | B14: 70
A15: jess | B15: 70
A16: summer | B16: 20
A17: Yi | B17: 0
