Workbook

Sheet FOH & BOH
A1: =+SUMMARY!A7 -> PAYROLL 26rd Sept- 23UGLY DUMPLING TEAM
A5: Employee Reference | B5: Employee Forename | C5: Employee Surname | D5: Pay Comp. Description | E5: H. Rate | F5: Units | G5: Pay | H5: Perf. Bonus | I5: Bonus | J5: Status | K5: S.Charge | L5: Notes
A6: Waitress | B6: Tamar | C6: Molina Rios | D6: Hourly Rate | E6: 10 | F6: 152.67 | G6: =E6*F6 -> 1526.7 | H6: 140 | K6: 2.5 | L6: pay rise £10
A7: Ass. Manager | B7: Lissette | C7: Paredes | D7: Hourly Rate | E7: 11 | F7: 101.81 | G7: =E7*F7 -> 1119.91 | H7: 90 | L7: Pay rise £11
A8: Ass. Manager | B8: Melanny Salome | C8: Folleco Chala | D8: Hourly Rate | E8: 10 | F8: 98.16 | G8: =E8*F8 -> 981.6 | H8: 50 | L8: Leaver
A9: Manager | B9: Sergio | C9: Ferrerosa | D9: Hourly Rate | E9: 11 | F9: 158.19 | G9: =E9*F9 -> 1740.09 | H9: 130 | K9: 3.5 | L9: pay rise to £11
A10: Ass. Manager | B10: David Daniel | C10: Molina Rios | D10: Hourly Rate | E10: 11 | F10: 181.09 | G10: =E10*F10 -> 1991.99 | H10: 140 | K10: 3 | L10: pay rise to £11
A11: Waitress | B11: Rochelle | C11: Jayaraj | D11: Hourly Rate | E11: 9 | F11: 140.61 | G11: =E11*F11 -> 1265.49 | K11: 1
A12: Waitress | B12: Karina | C12: Kavdanska | D12: Hourly Rate | E12: 9 | F12: 63.01 | G12: =E12*F12 -> 567.09 | K12: 1 | L12: pay rise £9
A13: Waitress | B13: Rebecca | C13: Archibold | D13: Hourly Rate | E13: 9 | F13: 69.12 | G13: =E13*F13 -> 622.08 | K13: 1 | L13: Leaver
A14: Waitress | B14: Endea | C14: Stractchan | D14: Hourly Rate | E14: 9 | F14: 100.71 | G14: =E14*F14 -> 906.39 | K14: 0.5
A15: Waitress | B15: Shania | C15: Malcolm | D15: Hourly Rate | E15: 9.5 | F15: 71.29 | G15: =E15*F15 -> 677.255 | K15: 0.5
A16: Waitress | B16: Benjamin | C16: Gray | D16: Hourly Rate | E16: 8.5 | F16: 81.6 | G16: =E16*F16 -> 693.6 | K16: 0.5 | L16: Starter
A17: Waitress | B17: Peace | C17: Imwensi | D17: Hourly Rate | E17: 8.5 | F17: 20.4 | G17: =E17*F17 -> 173.4 | K17: 0.5 | L17: Leaver
A18: Waitress | B18: Glenn | C18: Taniegra | D18: Hourly Rate | E18: 9.5 | F18: 123.64 | G18: =E18*F18 -> 1174.58 | K18: 1
A19: FOH&BOH | B19: Hubert | C19: Siotor | D19: Hourly Rate | E19: 10.5 | F19: 29.51 | G19: =E19*F19 -> 309.855 | K19: 1 | L19: Leaver
A20: Waiter | B20: Durba | C20: Chandan | D20: Hourly Rate | E20: 9.5 | F20: 15.35 | G20: =E20*F20 -> 145.825 | K20: 1 | L20: Starter
A21: Waiter | B21: Andrei | C21: Tiganus | D21: Hourly Rate | E21: 9.5 | F21: 21.46 | G21: =E21*F21 -> 203.87 | K21: 1 | L21: Starter
A22: Waitress | B22: Jc Marinel | C22: Navea | D22: Hourly Rate | E22: 8 | F22: =54.38+19.25 -> 73.63 | G22: =E22*F22 -> 589.04 | K22: 0.5
A24: Serior Chef | B24: Lorna | C24: Lau | D24: Hourly Rate | E24: 10 | F24: 21.37 | G24: =E24*F24 -> 213.7
A25: Kitchen Manager | B25: Dimitris | C25: Papachristos | D25: Hourly Rate | E25: 10.7 | F25: 156.22 | G25: =E25*F25 -> 1671.554 | H25: 160
A26: Kitchen Manager | B26: Jean Carlos | C26: Garcia Gonzalez | D26: Hourly Rate | E26: 10.7 | F26: 20 | G26: =E26*F26 -> 214 | L26: Month sick pay
A27: Prod. Team | B27: Wai Pink (Jess) | C27: Cham | D27: Hourly Rate | E27: 10 | F27: ='Dumpling Bonus '!G8 -> 72.37 | G27: =E27*F27 -> 723.7 | I27: =+'Dumpling Bonus '!J8 -> 27.8125
A28: Prod. Team | B28: Auntie WING | C28: Auntie Wing | D28: Hourly Rate | E28: 10 | F28: ='Dumpling Bonus '!$G7 -> 100.46 | G28: =E28*F28 -> 1004.6 | I28: ='Dumpling Bonus '!J7+50 -> 142.925
A29: Prod. Team | B29: Kitty | C29: Oil Lan | D29: Hourly Rate | E29: 9.5 | F29: 144.06 | G29: =E29*F29 -> 1368.57 | I29: 50
A30: Kitchen Staff | B30: Bruno | C30: Martins | D30: Hourly Rate | E30: 9.5 | F30: 154.08 | G30: =E30*F30 -> 1463.76 | H30: 80 | K30: 1
A31: Junior chef | B31: Adalgisa | C31: Vargas Feliz | D31: Hourly Rate | E31: 10 | F31: =20*4 -> 80 | G31: =E31*F31 -> 800 | K31: 3 | L31: pay rise to £10
A32: Junior chef | B32: Naomi Jhuliana | C32: Vallejos | D32: Hourly Rate | E32: 9 | F32: 83.68 | G32: =E32*F32 -> 753.12 | K32: 0.5 | L32: Holiday
A33: Junior chef | B33: Leonor | C33: Ferreira | D33: Hourly Rate | E33: 8.5 | F33: 95.88 | G33: =E33*F33 -> 814.98 | K33: 0.5 | L33: pay rise £8.5
A34: Junior chef | B34: Agata | C34: Drobinska | D34: Hourly Rate | E34: 8.5 | F34: 109.21 | G34: =E34*F34 -> 928.285 | K34: 1
A35: Kitchen Ass. Manager (training) | B35: Saicharan | C35: Manapalli | D35: Hourly Rate | E35: 10 | F35: =100 -> 100 | G35: =E35*F35 -> 1000 | H35: 130 | K35: 1
A36: Prod. Team | B36: Ling | C36: Chak | D36: Hourly Rate | E36: 9.5 | F36: 195.69 | G36: =E36*F36 -> 1859.055 | I36: 70
A37: Prod. Team | B37: Loh Kai Xuan Tabi | D37: Hourly Rate | E37: 8.5 | F37: 6 | G37: =E37*F37 -> 51
A38: Junior chef | B38: Olga | C38: Chala Quilumba | D38: Hourly Rate | E38: 9.5 | F38: 72.84 | G38: =E38*F38 -> 691.98 | K38: 2
A39: Junior chef | B39: Anny Belkys | C39: Matos | D39: Hourly Rate | E39: 9.5 | F39: 95.66 | G39: =E39*F39 -> 908.77 | K39: 2
A40: Junior chef | B40: Hafiz Abdur | C40: Rahim | D40: Hourly Rate | E40: 9.5 | F40: 132.16 | G40: =E40*F40 -> 1255.52 | K40: 1 | L40: Starter
A41: Junior chef | B41: Mei Lin | C41: Khong | D41: Hourly Rate | E41: 9.5 | F41: 60.48 | G41: =E41*F41 -> 574.56 | I41: 50 | L41: Starter
A42: Kitchen Ass. manager | B42: Setareh | C42: Saeedfar | D42: Hourly Rate | E42: 10.7 | F42: 115.38 | G42: =E42*F42 -> 1234.566 | K42: 1 | L42: 1 week Sick pay
A43: Junior chef | B43: Reyquane | C43: Kendell | D43: Hourly Rate | E43: 8.5 | F43: 98.89 | G43: =E43*F43 -> 840.565 | K43: 0.5 | L43: Starter
A44: Junior chef | B44: Adriana | C44: Baca | D44: Hourly Rate | E44: 10 | F44: 75.51 | G44: =E44*F44 -> 755.1 | K44: 1.5 | L44: Starter
...

Sheet SUMMARY
A7: PAYROLL 26rd Sept- 23UGLY DUMPLING TEAM
C13: TOTAL
B14: PAYROLL TOTAL | C14: ='FOH & BOH'!G47 -> 21182.863
B15: INCENTIVES | C15: ='FOH & BOH'!H47 -> 500
B16: DUMPLING BONUS | C16: ='FOH & BOH'!I47 -> 220.7375
B17: HOLIDAYS TOTAL | C17: ='HOLIDAYS AND NOTES'!F10 -> 2616
B18: TOTAL PAYROLL | C18: =SUM(C14:C17) -> 24519.6

Sheet HOLIDAYS AND NOTES
C1: =+SUMMARY!A7 -> PAYROLL 26rd Sept- 23UGLY DUMPLING TEAM
A3: HOLIDAYS
A5: Employee Forename | B5: Employee Surname | C5: Pay Component Description | D5: Rate | E5: Units | F5: TOTAL | G5: STATUS
A6: Salome | D6: 10 | E6: =15*8 -> 120 | F6: =D6*E6 -> 1200 | G6: Leaver
A7: Jhuli | D7: 9 | E7: =7*8 -> 56 | F7: =+D7*E7 -> 504
A8: Jess | D8: 9.5 | E8: =12*8 -> 96 | F8: =+E8*D8 -> 912
A10: TOTAL | F10: =+SUM(F6:F9) -> 2616

Sheet STARTERS DETAILS 
B1: =+SUMMARY!A7 -> PAYROLL 26rd Sept- 23UGLY DUMPLING TEAM
A2: NOTES
B11: New Startes | C11: NINo | E11: Bank Account N | F11: Sort Code | G11: Nationality | H11: Passaport nb | I11: Setlment status | J11: Share Code | K11: Resid. Card
B12: Durba Chandan | C12: TL615775D | E12: 28900363 | F12: 30.94.87
B13: Andrei Tiganus | C13: SX245757B | E13: 89327539 | F13: 04.00.04
B14: Arun Kumar Thota | C14: NA | E14: 22214272 | F14: 04.00.04 | G14: Indian | K14: RW3263394

Sheet Dumpling Bonus 
C6: Hours (deputy) | D6: Cash ded | E6: Dumlings (rep. wrappers) | F6: Total minus cash ded | G6: Hours red. By cash | I6: Total dump. Bonus | J6: Bonus | K6: bonus per hour | L6: hours after bonus
B7: Wing | C7: 180.46 | D7: =90*70 -> 6300 | E7: 15693 | F7: =E7-D7 -> 9393 | G7: =C7-B14 -> 100.46 | H7: =G7*$B$12 -> 7534.5 | I7: =F7-H7 -> 1858.5 | J7: =I7*$B$11 -> 92.925 | K7: =J7/G7 -> 0.92499502 | L7: =C7-B14 -> 100.46
B8: Jess | C8: 102.37 | D8: =$B$13*B15 -> 2700 | E8: 8684 | F8: =E8-D8 -> 5984 | G8: =C8-B15 -> 72.37 | H8: =G8*$B$12 -> 5427.75 | I8: =F8-H8 -> 556.25 | J8: =I8*$B$11 -> 27.8125 | K8: =J8/G8 -> 0.3843098 | L8: =C8-B15 -> 72.37
A10: Ref
A11: Bonus per dumpling | B11: 0.05
A12: Target | B12: 75
A13: Cash per 90 dumpl | B13: 90
A14: wing | B14: 80 | C14: hours
A15: jess | B15: 30
