Workbook

Sheet SUMMARY
A7: PAYROLL 20th Aug to 24th Sept UGLY DUMPLING TEAM
C13: TOTAL
B14: PAYROLL TOTAL | C14: ='Staff timesheets'!G41 -> 46779.233
B15: INCENTIVES | C15: ='Staff timesheets'!H41 -> 360
B16: HOLIDAYS TOTAL | C16: ='HOLIDAYS AND NOTES'!F16 -> 3760.32
B17: TOTAL PAYROLL | C17: =SUM(C14:C16) -> 50899.553

Sheet Staff timesheets
A3: Employee Reference | B3: Employee Forename | C3: Employee Surname | D3: Pay Comp. Description | E3: H. Rate | F3: Units | G3: Pay | H3: Perf. Bonus | I3: Special Arrang. Bonus | J3: Status | K3: S.Charge | L3: Notes
A4: Waitress | B4: Tamar | C4: Molina Rios | D4: Hourly Rate | E4: 10.5 | F4: 192.18 | G4: =(E4*F4)+K4*F4 -> 2498.34 | H4: 100 | K4: 2.5
A5: Ass. Manager | B5: Lissette | C5: Paredes | D5: Hourly Rate | E5: 11 | F5: 164.33 | G5: =(E5*F5)+K5*F5 -> 2464.95 | H5: 170 | K5: 4
A6: Ass. Manager | B6: David Daniel | C6: Molina Rios | D6: Hourly Rate | E6: 11 | F6: 195.85 | G6: =(E6*F6)+K6*F6 -> 2741.9 | H6: 120 | K6: 3
A7: Waitress | B7: Rochelle | C7: Jayaraj | D7: Hourly Rate | E7: 10 | F7: 135.37 | G7: =(E7*F7)+K7*F7 -> 1556.755 | K7: 1.5 | L7: Leaver
A8: Waitress | B8: Endea | C8: Stractchan | D8: Hourly Rate | E8: 10 | F8: 149.22 | G8: =(E8*F8)+K8*F8 -> 1641.42 | K8: 1
A9: Waitress | B9: Benjamin | C9: Gray | D9: Hourly Rate | E9: 10 | F9: 161.58 | G9: =(E9*F9)+K9*F9 -> 1777.38 | K9: 1 | L9: pay rise to £10
A10: Waitress | B10: Karina | C10: Kavdaska | D10: Hourly Rate | E10: 9 | F10: 61.83 | G10: =(E10*F10)+K10*F10 -> 618.3 | K10: 1 | L10: Leaver
A11: Waiter | B11: Archie | C11: Brice-Adams | D11: Hourly Rate | E11: 9.5 | F11: 66.81 | G11: =(E11*F11)+K11*F11 -> 668.1 | K11: 0.5 | L11: Leaver
A12: Waiter | B12: Durba | C12: Chandan | D12: Hourly Rate | E12: 10.42 | F12: 151.89 | G12: =(E12*F12)+K12*F12 -> 1734.5838 | K12: 1
A13: Waitress | B13: Melanny | C13: Folleco Chala | D13: Hourly Rate | E13: 10.42 | F13: 20.51 | G13: =(E13*F13)+K13*F13 -> 234.2242 | K13: 1 | L13: Decrease sc to £1
A14: Serior Chef | B14: Lorna | C14: Lau | D14: Hourly Rate | E14: 10.42 | F14: 29.56 | G14: =(E14*F14)+K14*F14 -> 308.0152
A15: Junior chef | B15: Heidy | C15: Ramos | D15: Hourly Rate | E15: =10.7+1 -> 11.7 | G15: =(E15*F15)+K15*F15 -> 0 | K15: 2
A16: Kitchen manager | B16: Setareh | C16: Saeedfar | D16: Hourly Rate | E16: =10.7+1.8 -> 12.5 | F16: 196.07 | G16: =(E16*F16)+K16*F16 -> 2646.945 | H16: 80 | K16: 1
A17: Kitchen Ass. Manager | B17: Saicharan | C17: Manapalli | D17: Hourly Rate | E17: 10.42 | G17: =(E17*F17)+K17*F17 -> 0 | K17: 1
A18: Junior chef | B18: Roger | C18: Rodriguez | D18: Hourly Rate | E18: 11 | F18: 144.79 | G18: =(E18*F18)+K18*F18 -> 1882.27 | H18: 100 | K18: 2 | L18: increase sc to 2
A19: Prod. Team | B19: Wai Pink (Jess) | C19: Cham | D19: Hourly Rate | E19: 10.42 | F19: 46.22 | G19: =(E19*F19)+K19*F19 -> 481.6124 | I19: =+'Dumpling Bonus '!J8+60 -> 101.175
A20: Prod. Team | B20: Auntie WING | C20: Auntie Wing | D20: Hourly Rate | E20: 11 | F20: 244.47 | G20: =(E20*F20)+K20*F20 -> 2933.64 | K20: 1
A21: Prod. Team | B21: Kitty | C21: Oil Lan | D21: Hourly Rate | E21: 10.42 | F21: 254.76 | G21: =(E21*F21)+K21*F21 -> 2654.5992
A22: Kitchen Staff | B22: Bruno | C22: Martins | D22: Hourly Rate | E22: 10 | F22: 223.05 | G22: =(E22*F22)+K22*F22 -> 2453.55 | H22: 100 | K22: 1
A23: Junior chef | B23: Adalgisa | C23: Vargas Feliz | D23: Hourly Rate | E23: 11 | F23: 80 | G23: =(E23*F23)+K23*F23 -> 1120 | K23: 3 | L23: pay increase t0 £11
A24: Junior chef | B24: Naomi Jhuliana | C24: Vallejos | D24: Hourly Rate | E24: 9 | F24: 63.65 | G24: =(E24*F24)+K24*F24 -> 604.675 | K24: 0.5
A25: Junior chef | B25: Luca | C25: Holden | D25: Hourly Rate | E25: 9 | F25: 41.85 | G25: =(E25*F25)+K25*F25 -> 397.575 | K25: 0.5 | L25: LEAVER
A26: Prod. Team | B26: Ling | C26: Chak | D26: Hourly Rate | E26: 10.42 | F26: 315.73 | G26: =(E26*F26)+K26*F26 -> 3289.9066 | H26: 80
A27: Prod. Team | B27: Luisa | C27: Valenzuela | D27: Hourly Rate | E27: 11 | F27: 77.66 | G27: =(E27*F27)+K27*F27 -> 931.92 | K27: 1
A28: Junior chef | B28: Olga | C28: Chala Quilumba | D28: Hourly Rate | E28: 10.42 | F28: 48.98 | G28: =(E28*F28)+K28*F28 -> 608.3316 | K28: 2
A29: Junior chef | B29: Anny Belkys | C29: Matos | D29: Hourly Rate | E29: 11 | F29: 83.48 | G29: =(E29*F29)+K29*F29 -> 1085.24 | K29: 2
A30: Junior chef | B30: Hafiz Abdur | C30: Rahim | D30: Hourly Rate | E30: 12 | F30: 157.17 | G30: =(E30*F30)+K30*F30 -> 1886.04
A31: Junior chef | B31: Adriana | C31: Baca | D31: Hourly Rate | E31: 11.4 | F31: 93 | G31: =(E31*F31)+K31*F31 -> 1199.7 | K31: 1.5
A32: Junior chef | B32: Eliana | C32: Sebastian | D32: Hourly Rate | E32: 9.5 | F32: 150.05 | G32: =(E32*F32)+K32*F32 -> 1500.5 | K32: 0.5
A33: Junior chef | B33: Marc | C33: Boltman | D33: Hourly Rate | E33: 10.42 | F33: 182.11 | G33: =(E33*F33)+K33*F33 -> 2261.8062 | K33: 2
B34: Celeste | C34: Mallison | D34: Hourly Rate | E34: 9 | F34: 13.2 | G34: =(E34*F34)+K34*F34 -> 118.8 | L34: Starter/Leaver
B35: Gabriella | C35: Walters | D35: Hourly Rate | E35: 9 | F35: 12.32 | G35: =(E35*F35)+K35*F35 -> 110.88 | L35: Starter/Leaver
B36: George | C36: Kelsey | D36: Hourly Rate | E36: 9.5 | F36: 75.12 | G36: =(E36*F36)+K36*F36 -> 713.64 | L36: Starter
B37: Grigori | C37: Bitiakov | D37: Hourly Rate | E37: 8 | F37: 54.29 | G37: =(E37*F37)+K37*F37 -> 434.32 | L37: Starter
B38: Ece Helena | C38: Yengil | D38: Hourly Rate | E38: 9 | F38: 29.68 | G38: =(E38*F38)+K38*F38 -> 267.12 | L38: Starter
B39: Iara | C39: Cabrita | D39: Hourly Rate | E39: 10.6 | F39: 44.14 | G39: =(E39*F39)+K39*F39 -> 467.884 | L39: Starter/Leaver
B40: Katie | C40: Russel | D40: Hourly Rate | E40: 9.5 | F40: 50.98 | G40: =(E40*F40)+K40*F40 -> 484.31
G41: =SUM(G4:G40) -> 46779.233 | H41: =SUM(H14:H40) -> 360 | I41: =SUM(I19:I21) -> 101.175
I48: {=5*tr} -> #NAME?
...

Sheet HOLIDAYS AND NOTES
C1: =+SUMMARY!A7 -> PAYROLL 20th Aug to 24th Sept UGLY DUMPLING TEAM
A3: HOLIDAYS
A5: Employee Forename | B5: Employee Surname | C5: Pay Component Description | D5: Rate | E5: Units | F5: TOTAL | G5: STATUS
A6: Rochelle | D6: 10.18 | E6: =4*8 -> 32 | F6: =+D6*E6 -> 325.76
A7: Jess | D7: 10.42 | E7: =10*8 -> 80 | F7: =+D7*E7 -> 833.6
A8: Roger | D8: 10.42 | E8: =12*8 -> 96 | F8: 672
A9: Olga | D9: 10.42 | E9: =2*8 -> 16 | F9: =+D9*E9 -> 166.72
A10: Eli | D10: 9 | E10: =4*8 -> 32 | F10: =+D10*E10 -> 288
A11: Setareh | D11: 11.5 | E11: =3*8 -> 24 | F11: =+D11*E11 -> 276 | G11: Leaver
A12: Hafiz | D12: 10.42 | E12: =5*8 -> 40 | F12: =+D12*E12 -> 416.8
A13: Luca | D13: 9 | E13: =2*8 -> 16 | F13: =+D13*E13 -> 144
A14: Archie | D14: 9.5 | E14: =4*8 -> 32 | F14: =+D14*E14 -> 304
A15: Mellany | D15: 10.42 | E15: =4*8 -> 32 | F15: =+D15*E15 -> 333.44 | G15: Leaver
A16: TOTAL | F16: =+SUM(F6:F15) -> 3760.32

Sheet STARTERS DETAILS 
B1: =+SUMMARY!A7 -> PAYROLL 20th Aug to 24th Sept UGLY DUMPLING TEAM
A2: NOTES
B11: New Startes | C11: NINo | E11: Bank Account N | F11: Sort Code | G11: Nationality | H11: Passaport nb | I11: Setlment status | J11: Sharing Code | K11: Resid. Card
B12: Celeste Mallison | C12: TL422019D | E12: 51191837 | F12: 40.11.60
B13: Gabriella Walters | C13: PK726309B | E13: 61373657 | F13: 09.01.29
B14: George Kelsey | C14: PK510269B | E14: 71679464 | F14: 04.29.09
B15: Grigori Bitiakov | C15: TJ199978C | E15: 34478594 | F15: 07.08.06
B16: Ece Henen Yengil | C16: PL305937B | E16: 39952862 | F16: 30.97.90
B17: Iara Cabrita | C17: SP426221B | E17: 66249405 | F17: 04.00.04
B18: Katie Russell | C18: PJ860108A | F18: 20.25.36

Sheet Dumpling Bonus 
C6: Hours (deputy) | D6: Cash ded | E6: Dumlings (rep. wrappers) | F6: Total minus cash ded | G6: Hours red. By cash | I6: Total dump. Bonus | J6: Bonus | K6: bonus per hour | L6: hours after bonus
B7: Wing | C7: 182.25 | D7: =+B15*B16 -> 7200 | E7: 9045 | F7: =E7-D7 -> 1845 | G7: =C7-B16 -> 102.25 | H7: =G7*$B$14 -> 7668.75 | I7: =F7-H7 -> -5823.75 | J7: =I7*$B$13 -> -291.1875 | K7: =J7/G7 -> -2.8477995 | L7: =C7-B16 -> 102.25
B8: Jess | C8: 169.74 | D8: =$B$15*B17 -> 7200 | E8: 14754 | F8: =E8-D8 -> 7554 | G8: =C8-B17 -> 89.74 | H8: =G8*$B$14 -> 6730.5 | I8: =F8-H8 -> 823.5 | J8: =I8*$B$13 -> 41.175 | K8: =J8/G8 -> 0.4588255 | L8: =C8-B17 -> 89.74
A12: Ref
A13: Bonus per dumpling | B13: 0.05
A14: Target | B14: 75
A15: Cash per 90 dumpl | B15: 90
A16: wing | B16: 80 | C16: hours
A17: jess | B17: 80
B18: 0
A19: Ling | B19: 0
B23: =5*20 -> 100
E24: 116.54
E25: =+E24*75 -> 8740.5
E26: 11119 | F26: =(E26-E25)*0.05 -> 118.925 | G26: =F26-50 -> 68.925
F27: =+F2 -> 0
G31: §
